Workbook

Sheet Summary
A1: TMT Camera production plan summary by part
A2: Upadte | B2: ='Monthly FC (Don''t use)'!E1 -> 46045
A3: Production Month | B3: ='Monthly FC (Don''t use)'!I1 -> Production Month:Feb'26
A4: NETH Doc
D5: 2021 | M5: 2022
A6: Part No. | B6: Model | D6: Mar | E6: Apr | F6: May | G6: Jun | H6: Jul | I6: Aug | J6: Sep | K6: Nov | L6: Dec | M6: Jan | N6: Feb | O6: Apr | P6: May | Q6: Jun | R6: Jul | S6: Aug | T6: Sep | U6: Oct | V6: Nov | W6: Dec | X6: Jan | Y6: Feb | Z6: Mar | AA6: Apr | AB6: May | AC6: Jun | AD6: Jul | AE6: Aug | AF6: Sep | AG6: Oct | AH6: Nov | AI6: Nov
A7: 86790-0K050-00 | B7: 867B | C7: Last FC | D7: 0 | E7: 34 | F7: 43 | G7: 8396 | H7: 8314 | I7: 13430 | J7: 22698 | K7: 13644 | L7: 17349 | M7: 19123 | N7: 18580 | P7: 18029 | Q7: 16437 | R7: 22295 | S7: 24394 | T7: 28530 | U7: 25510 | V7: 26808 | W7: 22098 | X7: 22011 | Y7: 25986 | Z7: 28830 | AA7: 21378 | AB7: 24514 | AC7: 23357 | AD7: 14462 | AE7: 25100
C8: Upadte | D8: 0 | F8: 43 | G8: 7380 | H8: 8373 | I8: 13277 | J8: 22558 | K8: 15740 | L8: 17349 | M8: 18652 | N8: 18126 | O8: 18474 | P8: 17226 | Q8: 15356 | R8: 19810 | S8: 24394 | T8: 27645 | U8: 25823 | V8: 23620 | W8: 21338 | X8: 22121 | Y8: 25812 | Z8: 29257 | AA8: 20054 | AB8: 17934 | AC8: 23167 | AD8: 14023 | AE8: 21562
C9: Diff | D9: =(D8-D7)/D8 -> #DIV/0! | E9: =(E8-E7)/E8 -> #DIV/0! | F9: =(F8-F7)/F8 -> 0 | G9: =(G8-G7)/G7 -> -0.12101 | H9: =(H8-H7)/H7 -> 0.0070964638 | I9: =(I8-I7)/I7 -> -0.011392405 | J9: =(J8-J7)/J7 -> -0.0061679443 | K9: =(K8-K7)/K7 -> 0.15362064 | L9: =(L8-L7)/L7 -> 0 | M9: =(M8-M7)/M7 -> -0.024630027 | N9: =(N8-N7)/N7 -> -0.024434876 | ... AI9: =(AI8-AI7)/AI7 -> #DIV/0!
A10: 86790-0K080-00 | B10: 867B | C10: Last FC | D10: 0 | E10: 5 | F10: 1414 | G10: 1640 | H10: 895 | I10: 1432 | J10: 2000 | K10: 1654 | L10: 1283 | M10: 1404 | N10: 1265 | P10: 2545 | Q10: 2189 | R10: 2115 | S10: 1436 | T10: 1305 | U10: 1652 | V10: 1293 | W10: 1974 | X10: 1769 | Y10: 2102 | Z10: 2823 | AA10: 2320 | AB10: 3658 | AC10: 2551 | AD10: 2215 | AE10: 2147
C11: Upadte | D11: 0 | F11: 5 | G11: 1294 | H11: 919 | I11: 1436 | J11: 2000 | K11: 1661 | L11: 1283 | M11: 1404 | N11: 1265 | O11: 1317 | P11: 2543 | Q11: 2329 | R11: 2118 | S11: 1436 | T11: 1630 | U11: 1288 | V11: 991 | W11: 1974 | X11: 1769 | Y11: 2102 | Z11: 2788 | AA11: 1910 | AB11: 3658 | AC11: 2542 | AD11: 1961 | AE11: 2147
C12: Diff | D12: =(D11-D10)/D11 -> #DIV/0! | E12: =(E11-E10)/E11 -> #DIV/0! | F12: =(F11-F10)/F11 -> -281.8 | G12: =(G11-G10)/G10 -> -0.21097561 | H12: =(H11-H10)/H10 -> 0.026815642 | I12: =(I11-I10)/I10 -> 0.0027932961 | J12: =(J11-J10)/J10 -> 0 | K12: =(K11-K10)/K10 -> 0.0042321644 | L12: =(L11-L10)/L10 -> 0 | M12: =(M11-M10)/M10 -> 0 | N12: =(N11-N10)/N10 -> 0 | ... AI12: =(AI11-AI10)/AI10 -> #DIV/0!
A13: 86790-0K110-00 | B13: 867B | C13: Last FC | D13: 0 | E13: 251 | F13: 11 | G13: 2088 | H13: 1071 | I13: 2336 | J13: 5312 | K13: 4274 | L13: 6041 | M13: 6987 | N13: 6243 | P13: 5991 | Q13: 6083 | R13: 16356 | S13: 7371 | T13: 9924 | U13: 6485 | V13: 5680 | W13: 6739 | X13: 8709 | Y13: 7803 | Z13: 7753 | AA13: 5551 | AB13: 5968 | AC13: 5755 | AD13: 4407 | AE13: 8337
C14: Upadte | D14: 0 | F14: 11 | G14: 1385 | H14: 1151 | I14: 2167 | J14: 5036 | K14: 4648 | L14: 6041 | M14: 7213 | N14: 6743 | O14: 4920 | P14: 5914 | Q14: 6089 | R14: 10891 | S14: 7371 | T14: 6356 | U14: 6774 | V14: 5886 | W14: 9919 | X14: 6299 | Y14: 7526 | Z14: 7661 | AA14: 5004 | AB14: 4188 | AC14: 5688 | AD14: 4349 | AE14: 7542
C15: Diff | D15: =(D14-D13)/D14 -> #DIV/0! | E15: =(E14-E13)/E14 -> #DIV/0! | F15: =(F14-F13)/F14 -> 0 | G15: =(G14-G13)/G13 -> -0.33668582 | H15: =(H14-H13)/H13 -> 0.074696545 | I15: =(I14-I13)/I13 -> -0.07234589 | J15: =(J14-J13)/J13 -> -0.051957831 | K15: =(K14-K13)/K13 -> 0.087505849 | L15: =(L14-L13)/L13 -> 0 | M15: =(M14-M13)/M13 -> 0.032345785 | N15: =(N14-N13)/N13 -> 0.0800897 | ... AI15: =(AI14-AI13)/AI13 -> #DIV/0!
A16: 86790-0K130-00 | B16: 867B | C16: Last FC | H16: 0 | I16: 46 | J16: 280 | K16: 1485 | L16: 3192 | M16: 3178 | N16: 3642 | P16: 2734 | Q16: 2519 | R16: 10223 | S16: 2740 | T16: 4120 | U16: 20 | V16: 0 | W16: 80 | X16: 0 | Y16: 60 | Z16: 120 | AA16: 40 | AB16: 80 | AC16: 120 | AD16: 60 | AE16: 60
C17: Upadte | G17: 0 | H17: 0 | I17: 60 | J17: 300 | K17: 780 | L17: 3240 | M17: 3040 | N17: 3620 | O17: 2380 | P17: 2720 | Q17: 2620 | R17: 3300 | S17: 2740 | T17: 20 | U17: 0 | V17: 220 | W17: 3800 | X17: 3860 | Y17: 120 | Z17: 120 | AA17: 40 | AB17: 100 | AC17: 40 | AD17: 60 | AE17: 40
C18: Diff | D18: =(D17-D16)/D17 -> #DIV/0! | E18: =(E17-E16)/E17 -> #DIV/0! | F18: =(F17-F16)/F17 -> #DIV/0! | G18: =(G17-G16)/G16 -> #DIV/0! | H18: =(H17-H16)/H16 -> #DIV/0! | I18: =(I17-I16)/I16 -> 0.30434783 | J18: =(J17-J16)/J16 -> 0.071428571 | K18: =(K17-K16)/K16 -> -0.47474747 | L18: =(L17-L16)/L16 -> 0.015037594 | M18: =(M17-M16)/M16 -> -0.043423537 | N18: =(N17-N16)/N16 -> -0.006040637 | ... AI18: =(AI17-AI16)/AI16 -> #DIV/0!
A19: 86790-0K140-A | B19: 867B | C19: Last FC | H19: 0 | I19: 46 | J19: 280 | K19: 1485 | L19: 3192 | M19: 3178 | N19: 3642 | P19: 0 | Q19: 0 | R19: 14 | S19: 693 | T19: 5257 | U19: 3952 | V19: 3432 | W19: 3185 | X19: 3356 | Y19: 4026 | Z19: 5032 | AA19: 2977 | AB19: 3481 | AC19: 3263 | AD19: 236 | AE19: 41
C20: Upadte | G20: 0 | H20: 0 | I20: 60 | J20: 300 | K20: 780 | L20: 3240 | M20: 3040 | N20: 3620 | O20: 0 | P20: 0 | Q20: 0 | R20: 52 | S20: 693 | T20: 3997 | U20: 3879 | V20: 3457 | W20: 3195 | X20: 3336 | Y20: 3816 | Z20: 5188 | AA20: 2723 | AB20: 3261 | AC20: 3630 | AD20: 113 | AE20: 917
C21: Diff | D21: =(D20-D19)/D20 -> #DIV/0! | E21: =(E20-E19)/E20 -> #DIV/0! | F21: =(F20-F19)/F20 -> #DIV/0! | G21: =(G20-G19)/G19 -> #DIV/0! | H21: =(H20-H19)/H19 -> #DIV/0! | I21: =(I20-I19)/I19 -> 0.30434783 | J21: =(J20-J19)/J19 -> 0.071428571 | K21: =(K20-K19)/K19 -> -0.47474747 | L21: =(L20-L19)/L19 -> 0.015037594 | M21: =(M20-M19)/M19 -> -0.043423537 | N21: =(N20-N19)/N19 -> -0.006040637 | ... AI21: =(AI20-AI19)/AI19 -> #DIV/0!
A22: 86790-0K170-A | B22: 867B | C22: Last FC | H22: 0 | I22: 46 | J22: 280 | K22: 1485 | L22: 3192 | M22: 3178 | N22: 3642 | P22: 0 | Q22: 0 | R22: 522 | S22: 5278 | T22: 5486 | U22: 5003 | V22: 5576 | W22: 4873 | X22: 5183 | Y22: 5285 | Z22: 5945 | AA22: 5274 | AB22: 4756 | AC22: 4894 | AD22: 2703 | AE22: 28
C23: Upadte | G23: 0 | H23: 0 | I23: 60 | J23: 300 | K23: 780 | L23: 3240 | M23: 3040 | N23: 3620 | O23: 0 | P23: 0 | Q23: 0 | R23: 925 | S23: 5278 | T23: 5679 | U23: 5653 | V23: 3997 | W23: 4653 | X23: 5243 | Y23: 5145 | Z23: 5853 | AA23: 4678 | AB23: 3816 | AC23: 4520 | AD23: 1336 | AE23: 586
C24: Diff | D24: =(D23-D22)/D23 -> #DIV/0! | E24: =(E23-E22)/E23 -> #DIV/0! | F24: =(F23-F22)/F23 -> #DIV/0! | G24: =(G23-G22)/G22 -> #DIV/0! | H24: =(H23-H22)/H22 -> #DIV/0! | I24: =(I23-I22)/I22 -> 0.30434783 | J24: =(J23-J22)/J22 -> 0.071428571 | K24: =(K23-K22)/K22 -> -0.47474747 | L24: =(L23-L22)/L22 -> 0.015037594 | M24: =(M23-M22)/M22 -> -0.043423537 | N24: =(N23-N22)/N22 -> -0.006040637 | ... AI24: =(AI23-AI22)/AI22 -> #DIV/0!
A25: 86790-0K180-A | B25: 867B | C25: Last FC | H25: 0 | I25: 46 | J25: 280 | K25: 1485 | L25: 3192 | M25: 3178 | N25: 3642 | P25: 0 | Q25: 0 | R25: 474 | S25: 1127 | T25: 3372 | U25: 2452 | V25: 1884 | W25: 2064 | X25: 2373 | Y25: 3161 | Z25: 3144 | AA25: 2126 | AB25: 2451 | AC25: 2386 | AD25: 224 | AE25: 0
C26: Upadte | G26: 0 | H26: 0 | I26: 60 | J26: 300 | K26: 780 | L26: 3240 | M26: 3040 | N26: 3620 | O26: 0 | P26: 0 | Q26: 0 | R26: 492 | S26: 1127 | T26: 2848 | U26: 2544 | V26: 2137 | W26: 1944 | X26: 2143 | Y26: 3071 | Z26: 3240 | AA26: 1963 | AB26: 2251 | AC26: 2245 | AD26: 82 | AE26: 0
C27: Diff | D27: =(D26-D25)/D26 -> #DIV/0! | E27: =(E26-E25)/E26 -> #DIV/0! | F27: =(F26-F25)/F26 -> #DIV/0! | G27: =(G26-G25)/G25 -> #DIV/0! | H27: =(H26-H25)/H25 -> #DIV/0! | I27: =(I26-I25)/I25 -> 0.30434783 | J27: =(J26-J25)/J25 -> 0.071428571 | K27: =(K26-K25)/K25 -> -0.47474747 | L27: =(L26-L25)/L25 -> 0.015037594 | M27: =(M26-M25)/M25 -> -0.043423537 | N27: =(N26-N25)/N25 -> -0.006040637 | ... AI27: =(AI26-AI25)/AI25 -> #DIV/0!
A28: 86790-0K190-B | B28: 867B | C28: Last FC | H28: 0 | I28: 46 | J28: 280 | K28: 1485 | L28: 3192 | M28: 3178 | N28: 3642 | P28: 0 | Q28: 0 | R28: 527 | S28: 551 | T28: 1101 | U28: 1288 | V28: 1214 | W28: 989 | X28: 793 | Y28: 1041 | Z28: 1137 | AA28: 1006 | AB28: 1008 | AC28: 1008 | AD28: 1262 | AE28: 2026
C29: Upadte | G29: 0 | H29: 0 | I29: 60 | J29: 300 | K29: 780 | L29: 3240 | M29: 3040 | N29: 3620 | O29: 0 | P29: 0 | Q29: 0 | R29: 546 | S29: 551 | T29: 852 | U29: 1399 | V29: 1154 | W29: 569 | X29: 834 | Y29: 999 | Z29: 1220 | AA29: 882 | AB29: 798 | AC29: 1134 | AD29: 1178 | AE29: 2110
C30: Diff | D30: =(D29-D28)/D29 -> #DIV/0! | E30: =(E29-E28)/E29 -> #DIV/0! | F30: =(F29-F28)/F29 -> #DIV/0! | G30: =(G29-G28)/G28 -> #DIV/0! | H30: =(H29-H28)/H28 -> #DIV/0! | I30: =(I29-I28)/I28 -> 0.30434783 | J30: =(J29-J28)/J28 -> 0.071428571 | K30: =(K29-K28)/K28 -> -0.47474747 | L30: =(L29-L28)/L28 -> 0.015037594 | M30: =(M29-M28)/M28 -> -0.043423537 | N30: =(N29-N28)/N28 -> -0.006040637 | ... AI30: =(AI29-AI28)/AI28 -> #DIV/0!
A31: 86790-0K120 | B31: 867B (BIS TKM) | C31: Last FC | X31: 0 | Y31: 500 | Z31: 378 | AA31: 0 | AB31: 0 | AC31: 320 | AD31: 0 | AE31: 240
C32: Upadte | W32: 0 | X32: 0 | Y32: 500 | Z32: 0 | AA32: 0 | AB32: 0 | AC32: 0 | AD32: 0 | AE32: 100
C33: Diff | W33: =(W32-W31)/W31 -> #DIV/0! | X33: =(X32-X31)/X31 -> #DIV/0! | Y33: =(Y32-Y31)/Y31 -> 0 | Z33: =(Z32-Z31)/Z31 -> -1 | AA33: =(AA32-AA31)/AA31 -> #DIV/0! | AB33: =(AB32-AB31)/AB31 -> #DIV/0! | AC33: =(AC32-AC31)/AC31 -> -1 | AD33: =(AD32-AD31)/AD31 -> #DIV/0! | ... AI33: =(AI32-AI31)/AI31 -> #DIV/0!
A34: 86790-0K200 | B34: 867B (BIS TKM) | C34: Last FC | X34: 0 | Y34: 1760 | Z34: 1700 | AA34: 2800 | AB34: 2800 | AC34: 3200 | AD34: 2780 | AE34: 900
C35: Upadte | W35: 0 | X35: 0 | Y35: 400 | Z35: 1700 | AA35: 2800 | AB35: 2800 | AC35: 3200 | AD35: 2780 | AE35: 1580
C36: Diff | W36: =(W35-W34)/W34 -> #DIV/0! | X36: =(X35-X34)/X34 -> #DIV/0! | Y36: =(Y35-Y34)/Y34 -> -0.77272727 | Z36: =(Z35-Z34)/Z34 -> 0 | AA36: =(AA35-AA34)/AA34 -> 0 | AB36: =(AB35-AB34)/AB34 -> 0 | AC36: =(AC35-AC34)/AC34 -> 0 | AD36: =(AD35-AD34)/AD34 -> 0 | ... AI36: =(AI35-AI34)/AI34 -> #DIV/0!
A37: 86790-0K220 | B37: 867B (BIS TKM) | C37: Last FC | X37: 0 | Y37: 3260 | Z37: 2580 | AA37: 3160 | AB37: 4620 | AC37: 3760 | AD37: 3460 | AE37: 3600
C38: Upadte | W38: 0 | X38: 0 | Y38: 1260 | Z38: 2640 | AA38: 3180 | AB38: 4120 | AC38: 3740 | AD38: 4400 | AE38: 0
C39: Diff | W39: =(W38-W37)/W37 -> #DIV/0! | X39: =(X38-X37)/X37 -> #DIV/0! | Y39: =(Y38-Y37)/Y37 -> -0.61349693 | Z39: =(Z38-Z37)/Z37 -> 0.023255814 | AA39: =(AA38-AA37)/AA37 -> 0.0063291139 | AB39: =(AB38-AB37)/AB37 -> -0.10822511 | AC39: =(AC38-AC37)/AC37 -> -0.0053191489 | AD39: =(AD38-AD37)/AD37 -> 0.2716763 | ... AI39: =(AI38-AI37)/AI37 -> #DIV/0!
A40: 86790-BZ270-J | B40: D33H (D26A) | C40: Last FC | S40: 0 | T40: 0 | U40: 0 | V40: 0 | W40: 1908 | X40: 1044 | Y40: 1476 | Z40: 1332 | AA40: 1152 | AB40: 1620 | AC40: 1404 | AD40: 3168 | AE40: 4320
...

Sheet By Plant
A1: By Plant
A2: Update | C2: 46045
A3: Production Month | C3: Feb'26 | D3: Firm-0 | H3: PO Dec
H4: =ROUND(SUBTOTAL(9,H8:H57),2) -> 67252 | I4: =ROUND(SUBTOTAL(9,I8:I57),2) -> 79486 | J4: =ROUND(SUBTOTAL(9,J8:J57),2) -> 66744 | K4: =ROUND(SUBTOTAL(9,K8:K57),2) -> 60180 | M4: =ROUND(SUBTOTAL(9,M8:M57),2) -> 67859 | N4: =ROUND(SUBTOTAL(9,N8:N57),2) -> 72308 | O4: =ROUND(SUBTOTAL(9,O8:O57),2) -> 68840
H5: Update | I5: Update | J5: Update | K5: Update | M5: Last FC | N5: Last FC | O5: Last FC | R5: Diff | S5: Diff | T5: Diff | W5: Diff | X5: Diff | Y5: Diff
A6: Part No. | B6: P/n | C6: Part Type | D6: Plant | E6: =B6&D6 -> P/nPlant | F6: Packing Type | G6: Packing Size | H6: Feb | I6: Mar | J6: Apr | K6: May | M6: =H6 -> Feb | N6: =I6 -> Mar | O6: =J6 -> Apr | P6: =K6 -> May | R6: =M6 -> Feb | S6: =N6 -> Mar | T6: =O6 -> Apr | U6: =P6 -> May | W6: =R6 -> Feb | X6: =S6 -> Mar | Y6: =T6 -> Apr | Z6: =U6 -> May | AB6: Remark to follow TDEM
A7: 86790-0K050 | B7: 86790-0K050 | C7: Back | D7: SR | E7: =B7&D7 -> 86790-0K050SR | F7: TP341 | G7: 25 | H7: =IFERROR(VLOOKUP($E7,Analyze!$B$62:$F$104,2,0),0) -> 0 | I7: =IFERROR(VLOOKUP($E7,Analyze!$B$62:$F$104,3,0),0) -> 0 | J7: =IFERROR(VLOOKUP($E7,Analyze!$B$62:$F$104,4,0),0) -> 0 | K7: =IFERROR(VLOOKUP($E7,Analyze!$B$62:$F$104,5,0),0) -> 0 | M7: 0 | N7: 0 | O7: 0 | R7: =H7-M7 -> 0 | S7: =I7-N7 -> 0 | T7: =J7-O7 -> 0 | W7: =(R7/M7) -> #DIV/0! | X7: =(S7/N7) -> #DIV/0! | Y7: =(T7/O7) -> #DIV/0!
A8: 86790-0K080-B | B8: 86790-0K080 | C8: Back | D8: SR | E8: =B8&D8 -> 86790-0K080SR | F8: TP341 | G8: 42 | H8: =IFERROR(VLOOKUP($E8,Analyze!$B$63:$F$105,2,0),0) -> 676 | I8: =IFERROR(VLOOKUP($E8,Analyze!$B$63:$F$105,3,0),0) -> 1170 | J8: =IFERROR(VLOOKUP($E8,Analyze!$B$63:$F$105,4,0),0) -> 1084 | K8: =IFERROR(VLOOKUP($E8,Analyze!$B$63:$F$105,5,0),0) -> 451 | M8: 676 | N8: 1209 | O8: 1093 | R8: =H8-M8 -> 0 | S8: =I8-N8 -> -39 | T8: =J8-O8 -> -9 | W8: =(R8/M8) -> 0 | X8: =(S8/N8) -> -0.032258065 | Y8: =(T8/O8) -> -0.0082342177
A9: 86790-0K141-A TP | B9: 86790-0K141 | C9: Front | D9: BPK | E9: =B9&D9&F9 -> 86790-0K141BPKTP1 | F9: TP1 | H9: =IFERROR(VLOOKUP($E9,Analyze!$B$63:$F$105,2,0),0) -> 0 | I9: =IFERROR(VLOOKUP($E9,Analyze!$B$63:$F$105,3,0),0) -> 0 | J9: =IFERROR(VLOOKUP($E9,Analyze!$B$63:$F$105,4,0),0) -> 0 | K9: =IFERROR(VLOOKUP($E9,Analyze!$B$63:$F$105,5,0),0) -> 0 | M9: 0 | N9: 0 | O9: 0 | R9: =H9-M9 -> 0 | S9: =I9-N9 -> 0 | T9: =J9-O9 -> 0 | W9: =(R9/M9) -> #DIV/0! | X9: =(S9/N9) -> #DIV/0! | Y9: =(T9/O9) -> #DIV/0!
A10: 86790-0K141 TP | D10: BPK | F10: TP1 | G10: 8 | H10: =IFERROR(VLOOKUP($E10,Analyze!$B$63:$F$105,2,0),0) -> 0 | I10: =IFERROR(VLOOKUP($E10,Analyze!$B$63:$F$105,3,0),0) -> 0 | J10: =IFERROR(VLOOKUP($E10,Analyze!$B$63:$F$105,4,0),0) -> 0 | K10: =IFERROR(VLOOKUP($E10,Analyze!$B$63:$F$105,5,0),0) -> 0 | M10: 0 | N10: 0 | O10: 0
A11: 86790-0K050 | B11: 86790-0K050 | C11: Back | D11: BP | E11: =B11&D11 -> 86790-0K050BP | F11: TP341 | G11: 25 | H11: =IFERROR(VLOOKUP($E11,Analyze!$B$63:$F$105,2,0),0) -> 0 | I11: =IFERROR(VLOOKUP($E11,Analyze!$B$63:$F$105,3,0),0) -> 0 | J11: =IFERROR(VLOOKUP($E11,Analyze!$B$63:$F$105,4,0),0) -> 0 | K11: =IFERROR(VLOOKUP($E11,Analyze!$B$63:$F$105,5,0),0) -> 0 | M11: 0 | N11: 0 | O11: 0 | R11: =H11-M11 -> 0 | S11: =I11-N11 -> 0 | T11: =J11-O11 -> 0 | W11: =(R11/M11) -> #DIV/0! | X11: =(S11/N11) -> #DIV/0! | Y11: =(T11/O11) -> #DIV/0!
A12: 86790-0K080-B | B12: 86790-0K080 | C12: Back | D12: BP | E12: =B12&D12 -> 86790-0K080BP | F12: TP341 | G12: 42 | H12: =IFERROR(VLOOKUP($E12,Analyze!$B$63:$F$105,2,0),0) -> 299 | I12: =IFERROR(VLOOKUP($E12,Analyze!$B$63:$F$105,3,0),0) -> 67 | J12: =IFERROR(VLOOKUP($E12,Analyze!$B$63:$F$105,4,0),0) -> 0 | K12: =IFERROR(VLOOKUP($E12,Analyze!$B$63:$F$105,5,0),0) -> 0 | M12: 299 | N12: 35 | O12: 0 | R12: =H12-M12 -> 0 | S12: =I12-N12 -> 32 | T12: =J12-O12 -> 0 | W12: =(R12/M12) -> 0 | X12: =(S12/N12) -> 0.91428571 | Y12: =(T12/O12) -> #DIV/0!
A13: 86790-0K110-B | B13: 86790-0K110 | C13: Back | D13: BP | E13: =B13&D13 -> 86790-0K110BP | F13: TP341 | G13: 18 | H13: =IFERROR(VLOOKUP($E13,Analyze!$B$63:$F$105,2,0),0) -> 1201 | I13: =IFERROR(VLOOKUP($E13,Analyze!$B$63:$F$105,3,0),0) -> 958 | J13: =IFERROR(VLOOKUP($E13,Analyze!$B$63:$F$105,4,0),0) -> 547 | K13: =IFERROR(VLOOKUP($E13,Analyze!$B$63:$F$105,5,0),0) -> 1185 | M13: 1201 | N13: 1058 | O13: 677 | R13: =H13-M13 -> 0 | S13: =I13-N13 -> -100 | T13: =J13-O13 -> -130 | W13: =(R13/M13) -> 0 | X13: =(S13/N13) -> -0.094517958 | Y13: =(T13/O13) -> -0.19202363
A14: 86790-0K141-A | B14: 86790-0K141 | C14: Front | D14: SR | E14: =B14&D14 -> 86790-0K141SR | F14: TP341 | G14: 8 | H14: =IFERROR(VLOOKUP($E14,Analyze!$B$63:$F$105,2,0),0) -> 2 | I14: =IFERROR(VLOOKUP($E14,Analyze!$B$63:$F$105,3,0),0) -> 4 | J14: =IFERROR(VLOOKUP($E14,Analyze!$B$63:$F$105,4,0),0) -> 0 | K14: =IFERROR(VLOOKUP($E14,Analyze!$B$63:$F$105,5,0),0) -> 0 | M14: 2 | N14: 4 | O14: 63 | R14: =H14-M14 -> 0 | S14: =I14-N14 -> 0 | T14: =J14-O14 -> -63 | W14: =(R14/M14) -> 0 | X14: =(S14/N14) -> 0 | Y14: =(T14/O14) -> -1
A15: 86790-0K141-A | B15: 86790-0K141 | C15: Front | D15: BP | E15: =B15&D15 -> 86790-0K141BP | F15: TP341 | G15: 8 | H15: =IFERROR(VLOOKUP($E15,Analyze!$B$63:$F$105,2,0),0) -> 232 | I15: =IFERROR(VLOOKUP($E15,Analyze!$B$63:$F$105,3,0),0) -> 336 | J15: =IFERROR(VLOOKUP($E15,Analyze!$B$63:$F$105,4,0),0) -> 59 | K15: =IFERROR(VLOOKUP($E15,Analyze!$B$63:$F$105,5,0),0) -> 0 | M15: 232 | N15: 194 | O15: 4 | R15: =H15-M15 -> 0 | S15: =I15-N15 -> 142 | T15: =J15-O15 -> 55 | W15: =(R15/M15) -> 0 | X15: =(S15/N15) -> 0.73195876 | Y15: =(T15/O15) -> 13.75
A16: 86790-0K141-A SN1 | B16: 86790-0K141 | C16: Front | D16: BPK | E16: =B16&D16 -> 86790-0K141BPK | F16: SN1 | H16: =IFERROR(VLOOKUP($E16,Analyze!$B$63:$F$105,2,0),0) -> 1712 | I16: =IFERROR(VLOOKUP($E16,Analyze!$B$63:$F$105,3,0),0) -> 2064 | J16: =IFERROR(VLOOKUP($E16,Analyze!$B$63:$F$105,4,0),0) -> 1392 | K16: =IFERROR(VLOOKUP($E16,Analyze!$B$63:$F$105,5,0),0) -> 912 | M16: 1760 | N16: 2000 | O16: 1712 | R16: =H16-M16 -> -48 | S16: =I16-N16 -> 64 | T16: =J16-O16 -> -320 | W16: =(R16/M16) -> -0.027272727 | X16: =(S16/N16) -> 0.032 | Y16: =(T16/O16) -> -0.18691589
A17: 86790-0K171 TP | D17: BPK | F17: TP1 | G17: 8 | H17: =IFERROR(VLOOKUP($E17,Analyze!$B$63:$F$105,2,0),0) -> 0 | I17: =IFERROR(VLOOKUP($E17,Analyze!$B$63:$F$105,3,0),0) -> 0 | J17: =IFERROR(VLOOKUP($E17,Analyze!$B$63:$F$105,4,0),0) -> 0 | K17: =IFERROR(VLOOKUP($E17,Analyze!$B$63:$F$105,5,0),0) -> 0 | M17: 0 | N17: 0 | O17: 0
A18: 86790-0K230-A | B18: 86790-0K230 | C18: Front | D18: BP | E18: =B18&D18 -> 86790-0K230BP | F18: TP341 | G18: 10 | H18: =IFERROR(VLOOKUP($E18,Analyze!$B$63:$F$105,2,0),0) -> 618 | I18: =IFERROR(VLOOKUP($E18,Analyze!$B$63:$F$105,3,0),0) -> 733 | J18: =IFERROR(VLOOKUP($E18,Analyze!$B$63:$F$105,4,0),0) -> 406 | K18: =IFERROR(VLOOKUP($E18,Analyze!$B$63:$F$105,5,0),0) -> 0 | M18: 618 | N18: 541 | O18: 408 | R18: =H18-M18 -> 0 | S18: =I18-N18 -> 192 | T18: =J18-O18 -> -2 | W18: =(R18/M18) -> 0 | X18: =(S18/N18) -> 0.35489834 | Y18: =(T18/O18) -> -0.0049019608
A19: 86790-0K050 SN1 | B19: 86790-0K050 | C19: Back | D19: BPK | E19: =B19&D19 -> 86790-0K050BPK | F19: SN1 | G19: 20 | H19: =IFERROR(VLOOKUP($E19,Analyze!$B$63:$F$105,2,0),0) -> 0 | I19: =IFERROR(VLOOKUP($E19,Analyze!$B$63:$F$105,3,0),0) -> 0 | J19: =IFERROR(VLOOKUP($E19,Analyze!$B$63:$F$105,4,0),0) -> 0 | K19: =IFERROR(VLOOKUP($E19,Analyze!$B$63:$F$105,5,0),0) -> 0 | M19: 0 | N19: 0 | O19: 0 | R19: =H19-M19 -> 0 | S19: =I19-N19 -> 0 | T19: =J19-O19 -> 0 | W19: =(R19/M19) -> #DIV/0! | X19: =(S19/N19) -> #DIV/0! | Y19: =(T19/O19) -> #DIV/0!
A20: 86790-0K050 TP | B20: 86790-0K050 | C20: Back | D20: BPK | E20: =B20&D20&F20 -> 86790-0K050BPKTP1 | F20: TP1 | G20: 25 | H20: =IFERROR(VLOOKUP($E20,Analyze!$B$63:$F$105,2,0),0) -> 0 | I20: =IFERROR(VLOOKUP($E20,Analyze!$B$63:$F$105,3,0),0) -> 0 | J20: =IFERROR(VLOOKUP($E20,Analyze!$B$63:$F$105,4,0),0) -> 0 | K20: =IFERROR(VLOOKUP($E20,Analyze!$B$63:$F$105,5,0),0) -> 0 | M20: 0 | N20: 0 | O20: 0 | R20: =H20-M20 -> 0 | S20: =I20-N20 -> 0 | T20: =J20-O20 -> 0 | W20: =(R20/M20) -> #DIV/0! | X20: =(S20/N20) -> #DIV/0! | Y20: =(T20/O20) -> #DIV/0!
A21: 86790-0K110-B SN1 | B21: 86790-0K110 | C21: Back | D21: BPK | E21: =B21&D21 -> 86790-0K110BPK | F21: SN1 | G21: 20 | H21: =IFERROR(VLOOKUP($E21,Analyze!$B$63:$F$105,2,0),0) -> 6680 | I21: =IFERROR(VLOOKUP($E21,Analyze!$B$63:$F$105,3,0),0) -> 6740 | J21: =IFERROR(VLOOKUP($E21,Analyze!$B$63:$F$105,4,0),0) -> 5120 | K21: =IFERROR(VLOOKUP($E21,Analyze!$B$63:$F$105,5,0),0) -> 4220 | M21: 6660 | N21: 5700 | O21: 5940 | R21: =H21-M21 -> 20 | S21: =I21-N21 -> 1040 | T21: =J21-O21 -> -820 | W21: =(R21/M21) -> 0.003003003 | X21: =(S21/N21) -> 0.18245614 | Y21: =(T21/O21) -> -0.13804714
A22: 86790-0K110-B TP | B22: 86790-0K110 | C22: Back | D22: BPK | E22: =B22&D22&F22 -> 86790-0K110BPKTP1 | F22: TP1 | G22: 18 | H22: =IFERROR(VLOOKUP($E22,Analyze!$B$63:$F$105,2,0),0) -> 170 | I22: =IFERROR(VLOOKUP($E22,Analyze!$B$63:$F$105,3,0),0) -> 380 | J22: =IFERROR(VLOOKUP($E22,Analyze!$B$63:$F$105,4,0),0) -> 130 | K22: =IFERROR(VLOOKUP($E22,Analyze!$B$63:$F$105,5,0),0) -> 210 | M22: 230 | N22: 170 | O22: 160 | R22: =H22-M22 -> -60 | S22: =I22-N22 -> 210 | T22: =J22-O22 -> -30 | W22: =(R22/M22) -> -0.26086957 | X22: =(S22/N22) -> 1.2352941 | Y22: =(T22/O22) -> -0.1875
A23: 86790-0K130 | B23: 86790-0K130 | C23: Back | D23: BPK | E23: =B23&D23 -> 86790-0K130BPK | F23: SN1 | G23: 20 | H23: =IFERROR(VLOOKUP($E23,Analyze!$B$63:$F$105,2,0),0) -> 0 | I23: =IFERROR(VLOOKUP($E23,Analyze!$B$63:$F$105,3,0),0) -> 0 | J23: =IFERROR(VLOOKUP($E23,Analyze!$B$63:$F$105,4,0),0) -> 0 | K23: =IFERROR(VLOOKUP($E23,Analyze!$B$63:$F$105,5,0),0) -> 0 | M23: 0 | N23: 0 | O23: 0 | R23: =H23-M23 -> 0 | S23: =I23-N23 -> 0 | T23: =J23-O23 -> 0 | W23: =(R23/M23) -> #DIV/0! | X23: =(S23/N23) -> #DIV/0! | Y23: =(T23/O23) -> #DIV/0!
A24: 86790-0K171-A | B24: 86790-0K171 | C24: Front | D24: SR | E24: =B24&D24 -> 86790-0K171SR | F24: TP341 | G24: 8 | H24: =IFERROR(VLOOKUP($E24,Analyze!$B$63:$F$105,2,0),0) -> 251 | I24: =IFERROR(VLOOKUP($E24,Analyze!$B$63:$F$105,3,0),0) -> 285 | J24: =IFERROR(VLOOKUP($E24,Analyze!$B$63:$F$105,4,0),0) -> 360 | K24: =IFERROR(VLOOKUP($E24,Analyze!$B$63:$F$105,5,0),0) -> 0 | M24: 251 | N24: 215 | O24: 364 | R24: =H24-M24 -> 0 | S24: =I24-N24 -> 70 | T24: =J24-O24 -> -4 | W24: =(R24/M24) -> 0 | X24: =(S24/N24) -> 0.3255814 | Y24: =(T24/O24) -> -0.010989011
A25: 86790-0K171-A | B25: 86790-0K171 | C25: Front | D25: BP | E25: =B25&D25 -> 86790-0K171BP | F25: TP341 | G25: 8 | H25: =IFERROR(VLOOKUP($E25,Analyze!$B$63:$F$105,2,0),0) -> 485 | I25: =IFERROR(VLOOKUP($E25,Analyze!$B$63:$F$105,3,0),0) -> 402 | J25: =IFERROR(VLOOKUP($E25,Analyze!$B$63:$F$105,4,0),0) -> 299 | K25: =IFERROR(VLOOKUP($E25,Analyze!$B$63:$F$105,5,0),0) -> 0 | M25: 485 | N25: 276 | O25: 295 | R25: =H25-M25 -> 0 | S25: =I25-N25 -> 126 | T25: =J25-O25 -> 4 | W25: =(R25/M25) -> 0 | X25: =(S25/N25) -> 0.45652174 | Y25: =(T25/O25) -> 0.013559322
A26: 86790-0K171-A SN1 | B26: 86790-0K171 | C26: Front | D26: BPK | E26: =B26&D26 -> 86790-0K171BPK | F26: SN1 | H26: =IFERROR(VLOOKUP($E26,Analyze!$B$63:$F$105,2,0),0) -> 0 | I26: =IFERROR(VLOOKUP($E26,Analyze!$B$63:$F$105,3,0),0) -> 0 | J26: =IFERROR(VLOOKUP($E26,Analyze!$B$63:$F$105,4,0),0) -> 0 | K26: =IFERROR(VLOOKUP($E26,Analyze!$B$63:$F$105,5,0),0) -> 0 | M26: 0 | N26: 0 | O26: 0 | R26: =H26-M26 -> 0 | S26: =I26-N26 -> 0 | T26: =J26-O26 -> 0 | W26: =(R26/M26) -> #DIV/0! | X26: =(S26/N26) -> #DIV/0! | Y26: =(T26/O26) -> #DIV/0!
A27: 86790-0K171-A TP | B27: 86790-0K171 | C27: Front | D27: BPK | E27: =B27&D27&F27 -> 86790-0K171BPKTP1 | F27: TP1 | H27: =IFERROR(VLOOKUP($E27,Analyze!$B$63:$F$105,2,0),0) -> 290 | I27: =IFERROR(VLOOKUP($E27,Analyze!$B$63:$F$105,3,0),0) -> 390 | J27: =IFERROR(VLOOKUP($E27,Analyze!$B$63:$F$105,4,0),0) -> 360 | K27: =IFERROR(VLOOKUP($E27,Analyze!$B$63:$F$105,5,0),0) -> 230 | M27: 440 | N27: 430 | O27: 350 | R27: =H27-M27 -> -150 | S27: =I27-N27 -> -40 | T27: =J27-O27 -> 10 | W27: =(R27/M27) -> -0.34090909 | X27: =(S27/N27) -> -0.093023256 | Y27: =(T27/O27) -> 0.028571429
A28: 86790-0K120-A | B28: 86790-0K120 | C28: Back | D28: BPK | E28: =B28&D28 -> 86790-0K120BPK | F28: SN1 | H28: =IFERROR(VLOOKUP($E28,Analyze!$B$63:$F$105,2,0),0) -> 240 | I28: =IFERROR(VLOOKUP($E28,Analyze!$B$63:$F$105,3,0),0) -> 360 | J28: =IFERROR(VLOOKUP($E28,Analyze!$B$63:$F$105,4,0),0) -> 200 | K28: =IFERROR(VLOOKUP($E28,Analyze!$B$63:$F$105,5,0),0) -> 20 | L28: BIS TKM | M28: 240 | N28: 360 | O28: 360 | R28: =H28-M28 -> 0 | S28: =I28-N28 -> 0 | T28: =J28-O28 -> -160 | W28: =(R28/M28) -> 0 | X28: =(S28/N28) -> 0 | Y28: =(T28/O28) -> -0.44444444
A29: 86790-0K200-A | B29: 86790-0K200 | C29: Back | D29: BPK | E29: =B29&D29 -> 86790-0K200BPK | F29: SN1 | H29: =IFERROR(VLOOKUP($E29,Analyze!$B$63:$F$105,2,0),0) -> 3020 | I29: =IFERROR(VLOOKUP($E29,Analyze!$B$63:$F$105,3,0),0) -> 2820 | J29: =IFERROR(VLOOKUP($E29,Analyze!$B$63:$F$105,4,0),0) -> 2880 | K29: =IFERROR(VLOOKUP($E29,Analyze!$B$63:$F$105,5,0),0) -> 2620 | L29: BIS TKM | M29: 3020 | N29: 2720 | O29: 2400 | R29: =H29-M29 -> 0 | S29: =I29-N29 -> 100 | T29: =J29-O29 -> 480 | W29: =(R29/M29) -> 0 | X29: =(S29/N29) -> 0.036764706 | Y29: =(T29/O29) -> 0.2
A30: 86790-0K220-A | B30: 86790-0K220 | C30: Back | D30: BPK | E30: =B30&D30 -> 86790-0K220BPK | F30: SN1 | H30: =IFERROR(VLOOKUP($E30,Analyze!$B$63:$F$105,2,0),0) -> 1160 | I30: =IFERROR(VLOOKUP($E30,Analyze!$B$63:$F$105,3,0),0) -> 2100 | J30: =IFERROR(VLOOKUP($E30,Analyze!$B$63:$F$105,4,0),0) -> 2040 | K30: =IFERROR(VLOOKUP($E30,Analyze!$B$63:$F$105,5,0),0) -> 1040 | L30: BIS TKM | M30: 1300 | N30: 2160 | O30: 2220 | R30: =H30-M30 -> -140 | S30: =I30-N30 -> -60 | T30: =J30-O30 -> -180 | W30: =(R30/M30) -> -0.10769231 | X30: =(S30/N30) -> -0.027777778 | Y30: =(T30/O30) -> -0.081081081
A31: 86790-0K230-A SN1 | B31: 86790-0K230 | C31: Front | D31: BPK | E31: =B31&D31 -> 86790-0K230BPK | F31: SN1 | H31: =IFERROR(VLOOKUP($E31,Analyze!$B$63:$F$105,2,0),0) -> 464 | I31: =IFERROR(VLOOKUP($E31,Analyze!$B$63:$F$105,3,0),0) -> 576 | J31: =IFERROR(VLOOKUP($E31,Analyze!$B$63:$F$105,4,0),0) -> 416 | K31: =IFERROR(VLOOKUP($E31,Analyze!$B$63:$F$105,5,0),0) -> 288 | M31: 432 | N31: 528 | O31: 464 | R31: =H31-M31 -> 32 | S31: =I31-N31 -> 48 | T31: =J31-O31 -> -48 | W31: =(R31/M31) -> 0.074074074 | X31: =(S31/N31) -> 0.090909091 | Y31: =(T31/O31) -> -0.10344828
A32: 86790-BZ270-J FC1 | B32: 86790-BZ270 | D32: GW | E32: =B32&D32 -> 86790-BZ270GW | F32: FC1 | H32: =IFERROR(VLOOKUP($E32,Analyze!$B$63:$F$105,2,0),0) -> 0 | I32: =IFERROR(VLOOKUP($E32,Analyze!$B$63:$F$105,3,0),0) -> 0 | J32: =IFERROR(VLOOKUP($E32,Analyze!$B$63:$F$105,4,0),0) -> 0 | K32: =IFERROR(VLOOKUP($E32,Analyze!$B$63:$F$105,5,0),0) -> 0 | M32: 0 | N32: 0 | O32: 0 | R32: =H32-M32 -> 0 | S32: =I32-N32 -> 0 | T32: =J32-O32 -> 0 | W32: =(R32/M32) -> #DIV/0! | X32: =(S32/N32) -> #DIV/0! | Y32: =(T32/O32) -> #DIV/0!
A33: 86790-BZ280-L SN1 | B33: 86790-BZ280 | D33: GW | E33: =B33&D33 -> 86790-BZ280GW | F33: SN1 | G33: 10 | H33: =IFERROR(VLOOKUP($E33,Analyze!$B$63:$F$105,2,0),0) -> 8210 | I33: =IFERROR(VLOOKUP($E33,Analyze!$B$63:$F$105,3,0),0) -> 5430 | J33: =IFERROR(VLOOKUP($E33,Analyze!$B$63:$F$105,4,0),0) -> 5520 | K33: =IFERROR(VLOOKUP($E33,Analyze!$B$63:$F$105,5,0),0) -> 5170 | M33: 8040 | N33: 5500 | O33: 5570 | R33: =H33-M33 -> 170 | S33: =I33-N33 -> -70 | T33: =J33-O33 -> -50 | W33: =(R33/M33) -> 0.021144279 | X33: =(S33/N33) -> -0.012727273 | Y33: =(T33/O33) -> -0.0089766607
A34: 86790-BZ210-L | B34: 86790-BZ210 | D34: GW | E34: =B34&D34 -> 86790-BZ210GW | F34: TP341 | H34: =IFERROR(VLOOKUP($E34,Analyze!$B$63:$F$105,2,0),0) -> 5651 | I34: =IFERROR(VLOOKUP($E34,Analyze!$B$63:$F$105,3,0),0) -> 7044 | J34: =IFERROR(VLOOKUP($E34,Analyze!$B$63:$F$105,4,0),0) -> 5224 | K34: =IFERROR(VLOOKUP($E34,Analyze!$B$63:$F$105,5,0),0) -> 7912 | M34: 5661 | N34: 6900 | O34: 5595 | R34: =H34-M34 -> -10 | S34: =I34-N34 -> 144 | T34: =J34-O34 -> -371 | W34: =(R34/M34) -> -0.0017664724 | X34: =(S34/N34) -> 0.020869565 | Y34: =(T34/O34) -> -0.066309205
A35: 86790-BZ220-K | B35: 86790-BZ220 | D35: GW | E35: =B35&D35 -> 86790-BZ220GW | F35: TP341 | H35: =IFERROR(VLOOKUP($E35,Analyze!$B$63:$F$105,2,0),0) -> 772 | I35: =IFERROR(VLOOKUP($E35,Analyze!$B$63:$F$105,3,0),0) -> 1388 | J35: =IFERROR(VLOOKUP($E35,Analyze!$B$63:$F$105,4,0),0) -> 733 | K35: =IFERROR(VLOOKUP($E35,Analyze!$B$63:$F$105,5,0),0) -> 1353 | M35: 772 | N35: 1133 | O35: 749 | R35: =H35-M35 -> 0 | S35: =I35-N35 -> 255 | T35: =J35-O35 -> -16 | W35: =(R35/M35) -> 0 | X35: =(S35/N35) -> 0.2250662 | Y35: =(T35/O35) -> -0.021361816
A36: 86790-BZ310-L SN1 | B36: 86790-BZ310 | D36: GW | E36: =B36&D36&F36 -> 86790-BZ310GWSN1 | F36: SN1 | H36: =IFERROR(VLOOKUP($E36,Analyze!$B$63:$F$105,2,0),0) -> 2670 | I36: =IFERROR(VLOOKUP($E36,Analyze!$B$63:$F$105,3,0),0) -> 2745 | J36: =IFERROR(VLOOKUP($E36,Analyze!$B$63:$F$105,4,0),0) -> 3840 | K36: =IFERROR(VLOOKUP($E36,Analyze!$B$63:$F$105,5,0),0) -> 2520 | M36: 2490 | N36: 2715 | O36: 3585 | R36: =H36-M36 -> 180 | S36: =I36-N36 -> 30 | T36: =J36-O36 -> 255 | W36: =(R36/M36) -> 0.072289157 | X36: =(S36/N36) -> 0.011049724 | Y36: =(T36/O36) -> 0.071129707
A37: 86790-BZ310-L | B37: 86790-BZ310 | D37: GW | E37: =B37&D37 -> 86790-BZ310GW | F37: TP341 | H37: =IFERROR(VLOOKUP($E37,Analyze!$B$63:$F$105,2,0),0) -> 3303 | I37: =IFERROR(VLOOKUP($E37,Analyze!$B$63:$F$105,3,0),0) -> 3505 | J37: =IFERROR(VLOOKUP($E37,Analyze!$B$63:$F$105,4,0),0) -> 2626 | K37: =IFERROR(VLOOKUP($E37,Analyze!$B$63:$F$105,5,0),0) -> 2831 | M37: 3303 | N37: 2705 | O37: 2697 | R37: =H37-M37 -> 0 | S37: =I37-N37 -> 800 | T37: =J37-O37 -> -71 | W37: =(R37/M37) -> 0 | X37: =(S37/N37) -> 0.29574861 | Y37: =(T37/O37) -> -0.026325547
A38: 86790-0K051-A | B38: 86790-0K051 | C38: Back | D38: BP | E38: =B38&D38 -> 86790-0K051BP | F38: TP341 | H38: =IFERROR(VLOOKUP($E38,Analyze!$B$63:$F$105,2,0),0) -> 1891 | I38: =IFERROR(VLOOKUP($E38,Analyze!$B$63:$F$105,3,0),0) -> 1677 | J38: =IFERROR(VLOOKUP($E38,Analyze!$B$63:$F$105,4,0),0) -> 919 | K38: =IFERROR(VLOOKUP($E38,Analyze!$B$63:$F$105,5,0),0) -> 0 | M38: 1891 | N38: 1159 | O38: 814 | R38: =H38-M38 -> 0 | S38: =I38-N38 -> 518 | T38: =J38-O38 -> 105 | W38: =(R38/M38) -> 0 | X38: =(S38/N38) -> 0.44693701 | Y38: =(T38/O38) -> 0.12899263
A39: 86790-0K051-A | B39: 86790-0K051 | C39: Back | D39: SR | E39: =B39&D39 -> 86790-0K051SR | F39: TP341 | G39: 25 | H39: =IFERROR(VLOOKUP($E39,Analyze!$B$63:$F$105,2,0),0) -> 1352 | I39: =IFERROR(VLOOKUP($E39,Analyze!$B$63:$F$105,3,0),0) -> 1787 | J39: =IFERROR(VLOOKUP($E39,Analyze!$B$63:$F$105,4,0),0) -> 2037 | K39: =IFERROR(VLOOKUP($E39,Analyze!$B$63:$F$105,5,0),0) -> 0 | M39: 1352 | N39: 1710 | O39: 2152 | R39: =H39-M39 -> 0 | S39: =I39-N39 -> 77 | T39: =J39-O39 -> -115 | W39: =(R39/M39) -> 0 | X39: =(S39/N39) -> 0.04502924 | Y39: =(T39/O39) -> -0.053438662
A40: 86790-0K051-A SN1 | B40: 86790-0K051 | C40: Back | D40: BPK | E40: =B40&D40&F40 -> 86790-0K051BPKSN1 | F40: SN1 | H40: =IFERROR(VLOOKUP($E40,Analyze!$B$63:$F$105,2,0),0) -> 5790 | I40: =IFERROR(VLOOKUP($E40,Analyze!$B$63:$F$105,3,0),0) -> 7980 | J40: =IFERROR(VLOOKUP($E40,Analyze!$B$63:$F$105,4,0),0) -> 5490 | K40: =IFERROR(VLOOKUP($E40,Analyze!$B$63:$F$105,5,0),0) -> 3720 | M40: 6090 | N40: 6090 | O40: 5130 | R40: =H40-M40 -> -300 | S40: =I40-N40 -> 1890 | T40: =J40-O40 -> 360 | W40: =(R40/M40) -> -0.049261084 | X40: =(S40/N40) -> 0.31034483 | Y40: =(T40/O40) -> 0.070175439
...

Sheet Monthly FC (Don't use)
D1: SCP Update | E1: ='By Plant'!C2 -> 46045 | I1: ="Production Month:"&'By Plant'!C3 -> Production Month:Feb'26
P3: change to 024J model | Q3: change to 024J model | R3: change to 024J model | S3: change to 024J model | T3: Sum Qty | U3: Check | V3: Last FC | W3: Last FC | X3: Last FC
P4: ='By Plant'!H6 -> Feb | Q4: ='By Plant'!I6 -> Mar | R4: ='By Plant'!J6 -> Apr | S4: ='By Plant'!K6 -> May | T4: =T7+T17+T31+T54 -> 288288 | U4: =T4=Total!N35 -> FALSE | V4: =P4 -> Feb | W4: =Q4 -> Mar | X4: =R4 -> Apr | Y4: =S4 -> May | AE4: =P4 -> Feb | AF4: =Q4 -> Mar | AG4: =R4 -> Apr | AH4: =S4 -> May | AJ4: =V4 -> Feb | AK4: =W4 -> Mar | AL4: =X4 -> Apr | AM4: =Y4 -> May
D5: SAMRONG | E5: =E2 -> 0 | I5: Firm-0 | P5: Quantity | Q5: Forecast Quantity | V5: Last Forecast | AE5: Compare FC | AJ5: Compare FC
D6: Sl. No. | E6: Part No. | I6: Part Code | J6: Part Description | K6: Dock Code | L6: Shipping Dock | M6: Packing Size | N6: Plant | P6: (N) | Q6: N+1 | R6: N+2 | S6: N+3 | V6: (N) | W6: N+1 | X6: N+2 | Y6: N+3 | AA6: Diff | AB6: Diff | AC6: Diff | AE6: (N) | AF6: N+1 | AG6: N+2 | AH6: N+3 | AJ6: (N) | AK6: N+1 | AL6: N+2 | AM6: N+3 | AO6: TDEM PIC | AP6: E-mail | AQ6: Request | AR6: Reason feed back from TDEM
A7: SR | B7: Veh | C7: 438D> 481D | D7: 1 | E7: 86790-0K051-00 | I7: L342 | J7: CAMERA ASSY TELEVISION | K7: S1 | L7: 024J | M7: 25 | N7: SR | O7: =LEFT(E7,11)&N7 -> 86790-0K051SR | P7: 2893 | Q7: 2992 | R7: 950 | S7: 1258 | T7: =SUM(P7:S12) -> 13654 | U7: =T7='SR Daily'!EG20 -> FALSE | V7: 2893 | W7: 2913 | X7: 2946 | Y7: 0 | AA7: =P7-V7 -> 0 | AB7: =Q7-W7 -> 79 | AC7: =R7-X7 -> -1996 | AE7: =P7/V7 -> 1 | AF7: =Q7/W7 -> 1.0271198 | AG7: =R7/X7 -> 0.32247115 | AJ7: =AA7/V7 -> 0 | AK7: =AB7/W7 -> 0.027119808 | AL7: =AC7/X7 -> -0.67752885 | AN7: x | AO7: Kittipod Trirattanavanich | AP7: ktriratt@toyota.co.th | AQ7: demand sudden decrease in Dec 20%
A8: SR | B8: Veh | C8: 438D> 481D | D8: 2 | E8: 86790-0K080-00 | I8: G871 | J8: CAMERA ASSY TELEVISION | K8: S1 | L8: 024J | M8: 42 | N8: SR | O8: =LEFT(E8,11)&N8 -> 86790-0K080SR | P8: 745 | Q8: 503 | R8: 523 | S8: 661 | V8: 745 | W8: 595 | X8: 630 | Y8: 0 | AA8: =P8-V8 -> 0 | AB8: =Q8-W8 -> -92 | AC8: =R8-X8 -> -107 | AE8: =P8/V8 -> 1 | AF8: =Q8/W8 -> 0.84537815 | AG8: =R8/X8 -> 0.83015873 | AJ8: =AA8/V8 -> 0 | AK8: =AB8/W8 -> -0.15462185 | AL8: =AC8/X8 -> -0.16984127 | AN8: x | AO8: Kittipod Trirattanavanich | AP8: ktriratt@toyota.co.th | AQ8: demand sudden increase in Dec and Jan 40%
A9: SR | B9: Veh | C9: 438D> 481D | D9: 3 | E9: 86790-0K141-00 | I9: J788 | J9: CAMERA ASSY TELEVISION | K9: S1 | L9: 024J | M9: 8 | N9: SR | O9: =LEFT(E9,11)&N9 -> 86790-0K141SR | P9: 26 | Q9: 12 | R9: 9 | S9: 9 | V9: 26 | W9: 13 | X9: 13 | Y9: 0 | AA9: =P9-V9 -> 0 | AB9: =Q9-W9 -> -1 | AC9: =R9-X9 -> -4 | AE9: =P9/V9 -> 1 | AF9: =Q9/W9 -> 0.92307692 | AG9: =R9/X9 -> 0.69230769 | AJ9: =AA9/V9 -> 0 | AK9: =AB9/W9 -> -0.076923077 | AL9: =AC9/X9 -> -0.30769231 | AO9: Kittipod Trirattanavanich | AP9: ktriratt@toyota.co.th
A10: SR | B10: Veh | C10: 438D> 481D | D10: 4 | E10: 86790-0K171-00 | I10: J789 | J10: CAMERA ASSY TELEVISION | K10: S1 | L10: 024J | M10: 8 | N10: SR | O10: =LEFT(E10,11)&N10 -> 86790-0K171SR | P10: 726 | Q10: 308 | R10: 372 | S10: 523 | V10: 726 | W10: 465 | X10: 437 | Y10: 0 | AA10: =P10-V10 -> 0 | AB10: =Q10-W10 -> -157 | AC10: =R10-X10 -> -65 | AE10: =P10/V10 -> 1 | AF10: =Q10/W10 -> 0.66236559 | AG10: =R10/X10 -> 0.85125858 | AJ10: =AA10/V10 -> 0 | AK10: =AB10/W10 -> -0.33763441 | AL10: =AC10/X10 -> -0.14874142 | AN10: x | AO10: Kittipod Trirattanavanich | AP10: ktriratt@toyota.co.th | AQ10: demand sudden decrease in Dec 40%
A11: SR | B11: Veh | C11: 581D | D11: 5 | E11: 86790-0K310-00 | I11: N748 | J11: CAMERA ASSY TELEVISION | K11: S1 | L11: 024J | M11: 25 | P11: 164 | Q11: 44 | R11: 174 | S11: 190 | V11: 138 | W11: 38 | X11: 194 | AA11: =P11-V11 -> 26 | AB11: =Q11-W11 -> 6 | AC11: =R11-X11 -> -20 | AJ11: =AA11/V11 -> 0.1884058 | AK11: =AB11/W11 -> 0.15789474 | AL11: =AC11/X11 -> -0.10309278
A12: SR | B12: Veh | C12: 581D | D12: 6 | E12: 86790-0K400-00 | I12: N749 | J12: CAMERA ASSY TELEVISION | K12: S1 | L12: 024J | M12: 38 | P12: 164 | Q12: 44 | R12: 174 | S12: 190 | V12: 138 | W12: 38 | X12: 194 | AA12: =P12-V12 -> 26 | AB12: =Q12-W12 -> 6 | AC12: =R12-X12 -> -20 | AJ12: =AA12/V12 -> 0.1884058 | AK12: =AB12/W12 -> 0.15789474 | AL12: =AC12/X12 -> -0.10309278
R14: change to 024J model | S14: change to 024J model
D15: Banpho | E15: =E4 -> 0 | I15: =I4 -> 0 | P15: =P4 -> Feb | Q15: =Q4 -> Mar | R15: =R4 -> Apr | S15: =S4 -> May | V15: Last Forecast | AE15: Compare FC | AJ15: Compare FC
D16: Sl. No. | E16: Part No. | I16: Part Code | J16: Part Description | K16: Dock Code | L16: Shipping Dock | M16: Packing Size | N16: Plant | P16: (N) | Q16: N+1 | R16: N+2 | S16: N+3 | V16: (N) | W16: N+1 | X16: N+2 | Y16: N+3 | AE16: (N) | AF16: N+1 | AG16: N+2 | AH16: N+3 | AJ16: (N) | AK16: N+1 | AL16: N+2 | AM16: N+3
A17: BP | B17: Veh | C17: 438D> 481D | D17: 1 | E17: 86790-0K051-00 | F17: 86790-0K051-00 | H17: =F17=E17 -> TRUE | I17: I338 | J17: CAMERA ASSY TELEVISION | K17: P1 | L17: 975W/ 438D>>> 024J | M17: 25 | N17: BP | O17: =LEFT(E17,11)&N17 -> 86790-0K051BP | P17: 4401 | Q17: 3927 | R17: 2234 | S17: 1836 | T17: =SUM(P17:S26) -> 39022 | U17: =T17='BP Daily'!EG26 -> FALSE | V17: 4401 | W17: 4074 | X17: 2242 | AA17: =P17-V17 -> 0 | AB17: =Q17-W17 -> -147 | AC17: =R17-X17 -> -8 | AE17: =P17/V17 -> 1 | AF17: =Q17/W17 -> 0.96391753 | AG17: =R17/X17 -> 0.99643176 | AJ17: =AA17/V17 -> 0 | AK17: =AB17/W17 -> -0.036082474 | AL17: =AC17/X17 -> -0.0035682426 | AO17: Pongsakorn Meesuk | AP17: pmeesuk@toyota.co.th
A18: BP | B18: Veh | C18: 438D> 481D | D18: 2 | E18: 86790-0K080-00 | F18: 86790-0K080-00 | H18: =F18=E18 -> TRUE | I18: A369 | J18: CAMERA ASSY TELEVISION | K18: P1 | L18: 975W/ 438D>>> 024J | M18: 42 | N18: BP | O18: =LEFT(E18,11)&N18 -> 86790-0K080BP | P18: 619 | Q18: 553 | R18: 514 | S18: 380 | V18: 619 | W18: 516 | X18: 488 | AA18: =P18-V18 -> 0 | AB18: =Q18-W18 -> 37 | AC18: =R18-X18 -> 26 | AE18: =P18/V18 -> 1 | AF18: =Q18/W18 -> 1.0717054 | AG18: =R18/X18 -> 1.0532787 | AJ18: =AA18/V18 -> 0 | AK18: =AB18/W18 -> 0.071705426 | AL18: =AC18/X18 -> 0.053278689 | AN18: x | AO18: Pongsakorn Meesuk | AP18: pmeesuk@toyota.co.th | AQ18: demand sudden increase in Dec 30%
A19: BP | B19: Veh | C19: 438D> 481D | D19: 3 | E19: 86790-0K110-00 | F19: 86790-0K110-00 | H19: =F19=E19 -> TRUE | I19: A370 | J19: CAMERA ASSY TELEVISION | K19: P1 | L19: 975W/ 438D>>> 024J | M19: 18 | N19: BP | O19: =LEFT(E19,11)&N19 -> 86790-0K110BP | P19: 604 | Q19: 1218 | R19: 976 | S19: 834 | V19: 604 | W19: 1138 | X19: 886 | AA19: =P19-V19 -> 0 | AB19: =Q19-W19 -> 80 | AC19: =R19-X19 -> 90 | AE19: =P19/V19 -> 1 | AF19: =Q19/W19 -> 1.0702988 | AG19: =R19/X19 -> 1.1015801 | AJ19: =AA19/V19 -> 0 | AK19: =AB19/W19 -> 0.07029877 | AL19: =AC19/X19 -> 0.10158014 | AO19: Pongsakorn Meesuk | AP19: pmeesuk@toyota.co.th
A20: BP | B20: Veh | C20: 438D> 481D | D20: 4 | E20: 86790-0K141-00 | F20: 86790-0K141-00 | H20: =F20=E20 -> TRUE | I20: F165 | J20: CAMERA ASSY TELEVISION | K20: P1 | L20: 975W/ 438D>>> 024J | M20: 8 | N20: BP | O20: =LEFT(E20,11)&N20 -> 86790-0K141BP | P20: 522 | Q20: 416 | R20: 192 | S20: 127 | V20: 522 | W20: 200 | X20: 200 | AA20: =P20-V20 -> 0 | AB20: =Q20-W20 -> 216 | AC20: =R20-X20 -> -8 | AE20: =P20/V20 -> 1 | AF20: =Q20/W20 -> 2.08 | AG20: =R20/X20 -> 0.96 | AJ20: =AA20/V20 -> 0 | AK20: =AB20/W20 -> 1.08 | AL20: =AC20/X20 -> -0.04 | AN20: x | AO20: Pongsakorn Meesuk | AP20: pmeesuk@toyota.co.th | AQ20: demand sudden increase in Dec and Jan >50%
A21: BP | B21: Veh | C21: 438D> 481D | D21: 5 | E21: 86790-0K171-00 | F21: 86790-0K171-00 | H21: =F21=E21 -> TRUE | I21: F320 | J21: CAMERA ASSY TELEVISION | K21: P1 | L21: 975W/ 438D>>> 024J | M21: 8 | N21: BP | O21: =LEFT(E21,11)&N21 -> 86790-0K171BP | P21: 1518 | Q21: 1222 | R21: 740 | S21: 583 | V21: 1518 | W21: 1329 | X21: 826 | AA21: =P21-V21 -> 0 | AB21: =Q21-W21 -> -107 | AC21: =R21-X21 -> -86 | AE21: =P21/V21 -> 1 | AF21: =Q21/W21 -> 0.91948834 | AG21: =R21/X21 -> 0.89588378 | AJ21: =AA21/V21 -> 0 | AK21: =AB21/W21 -> -0.080511663 | AL21: =AC21/X21 -> -0.10411622 | AO21: Pongsakorn Meesuk | AP21: pmeesuk@toyota.co.th
A22: BP | B22: Veh | C22: 438D> 481D | D22: 6 | E22: 86790-0K181-00 | F22: 86790-0K181-00 | H22: =F22=E22 -> TRUE | I22: F323 | J22: CAMERA ASSY TELEVISION | K22: P1 | L22: 975W/ 438D>>> 024J | M22: 8 | N22: BP | O22: =LEFT(E22,11)&N22 -> 86790-0K181BP | P22: 99 | Q22: 48 | R22: 41 | S22: 39 | V22: 99 | W22: 47 | X22: 45 | AA22: =P22-V22 -> 0 | AB22: =Q22-W22 -> 1 | AC22: =R22-X22 -> -4 | AE22: =P22/V22 -> 1 | AF22: =Q22/W22 -> 1.0212766 | AG22: =R22/X22 -> 0.91111111 | AJ22: =AA22/V22 -> 0 | AK22: =AB22/W22 -> 0.021276596 | AL22: =AC22/X22 -> -0.088888889 | AO22: Pongsakorn Meesuk | AP22: pmeesuk@toyota.co.th
A23: BP | B23: Veh | C23: 438D> 481D | D23: 7 | E23: 86790-0K190-00 | F23: 86790-0K190-00 | H23: =F23=E23 -> TRUE | I23: D331 | J23: CAMERA ASSY TELEVISION | K23: P1 | L23: 975W/ 438D>>> 024J | M23: 6 | N23: BP | O23: =LEFT(E23,11)&N23 -> 86790-0K190BP | P23: 122 | Q23: 625 | R23: 479 | S23: 409 | V23: 122 | W23: 562 | X23: 433 | AA23: =P23-V23 -> 0 | AB23: =Q23-W23 -> 63 | AC23: =R23-X23 -> 46 | AE23: =P23/V23 -> 1 | AF23: =Q23/W23 -> 1.1120996 | AG23: =R23/X23 -> 1.1062356 | AJ23: =AA23/V23 -> 0 | AK23: =AB23/W23 -> 0.11209964 | AL23: =AC23/X23 -> 0.10623557 | AN23: x | AO23: Pongsakorn Meesuk | AP23: pmeesuk@toyota.co.th
A24: BP | B24: Veh | C24: 438D> 481D | D24: 8 | E24: 86790-0K230-00 | F24: 86790-0K230-00 | H24: =F24=E24 -> TRUE | I24: F530 | J24: CAMERA ASSY TELEVISION | K24: P1 | L24: 975W/ 438D>>> 024J | M24: 10 | N24: BP | O24: =LEFT(E24,11)&N24 -> 86790-0K230BP | P24: 640 | Q24: 785 | R24: 690 | S24: 669 | V24: 640 | W24: 761 | X24: 680 | AA24: =P24-V24 -> 0 | AB24: =Q24-W24 -> 24 | AC24: =R24-X24 -> 10 | AE24: =P24/V24 -> 1 | AF24: =Q24/W24 -> 1.0315375 | AG24: =R24/X24 -> 1.0147059 | AJ24: =AA24/V24 -> 0 | AK24: =AB24/W24 -> 0.031537451 | AL24: =AC24/X24 -> 0.014705882 | AO24: Pongsakorn Meesuk | AP24: pmeesuk@toyota.co.th
A25: BP | B25: Veh | C25: 581D | D25: 9 | E25: 86790-0K310-00 | I25: AU19 | J25: CAMERA ASSY TELEVISION | K25: E1,P1 | L25: 025J | M25: 25 | P25: 592 | Q25: 1812 | R25: 1486 | S25: 1590 | V25: 494 | W25: 1818 | X25: 1498 | AA25: =P25-V25 -> 98 | AB25: =Q25-W25 -> -6 | AC25: =R25-X25 -> -12 | AJ25: =AA25/V25 -> 0.19838057 | AK25: =AB25/W25 -> -0.00330033 | AL25: =AC25/X25 -> -0.0080106809
A26: BP | B26: Veh | C26: 581D | D26: 11 | E26: 86790-0K400-00 | I26: AU20 | J26: CAMERA ASSY TELEVISION | K26: E1,P1 | L26: 025J | M26: 38 | P26: 592 | Q26: 1812 | R26: 1486 | S26: 1590 | V26: 494 | W26: 1818 | X26: 1498 | AA26: =P26-V26 -> 98 | AB26: =Q26-W26 -> -6 | AC26: =R26-X26 -> -12 | AJ26: =AA26/V26 -> 0.19838057 | AK26: =AB26/W26 -> -0.00330033 | AL26: =AC26/X26 -> -0.0080106809
D29: BPK | E29: =E2 -> 0 | I29: =I5 -> Firm-0 | P29: =P15 -> Feb | Q29: =Q15 -> Mar | R29: =R15 -> Apr | S29: =S15 -> May | V29: Last Forecast | AE29: Compare FC | AJ29: Compare FC
D30: Sl. No. | E30: Part No. | I30: Part Code | J30: Part Description | K30: Dock Code | L30: Model | M30: Packing Size | N30: Plant | P30: (N) | Q30: N+1 | R30: N+2 | S30: N+3 | V30: (N) | W30: N+1 | X30: N+2 | Y30: N+3 | AE30: (N) | AF30: N+1 | AG30: N+2 | AH30: N+3 | AJ30: (N) | AK30: N+1 | AL30: N+2 | AM30: N+3
A31: BPK | B31: Packing | D31: TP1 | E31: 86790-0K050-00 | F31: 86790-0K050-00 | G31: =F31&K31 -> 86790-0K050-00B2 | H31: =F31=E31 -> TRUE | I31: M666 | J31: CAMERA ASSY TELEVISION | K31: B2 | L31: 889W | M31: 25 | N31: BPK | O31: =LEFT(E31,11)&N31&D31 -> 86790-0K050BPKTP1 | P31: 0 | Q31: 0 | R31: 0 | S31: 0 | T31: =SUM(P31:S47) -> 115905 | U31: =T31='BPK Daily'!EG39 -> FALSE | V31: 0 | W31: 0 | X31: 0 | AA31: =P31-V31 -> 0 | AB31: =Q31-W31 -> 0 | AC31: =R31-X31 -> 0 | AE31: =P31/V31 -> #DIV/0! | AF31: =Q31/W31 -> #DIV/0! | AG31: =R31/X31 -> #DIV/0! | AJ31: =AA31/V31 -> #DIV/0! | AK31: =AB31/W31 -> #DIV/0! | AL31: =AC31/X31 -> #DIV/0! | AO31: Ms. Manusanan Songpichet / Ms. Teeraporn Siritaweewat | AP31: manusanan_son@toyota-asia.com / teeraporn_sir@toyota-asia.com
A32: BPK | B32: Packing | D32: 86790-0K130-00 | E32: 86790-0K220-00 | F32: 86790-0K220-00 | G32: =F32&K32 -> 86790-0K220-00D1 | H32: =F32=E32 -> TRUE | I32: T742 | J32: CAMERA ASSY TELEVISION | K32: D1 | L32: 758W | M32: 20 | N32: BPK | O32: =LEFT(E32,11)&N32 -> 86790-0K220BPK | P32: 500 | Q32: 860 | R32: 1240 | S32: 1080 | T32: BIS EOL | V32: 600 | W32: 840 | X32: 1240 | AA32: =P32-V32 -> -100 | AB32: =Q32-W32 -> 20 | AC32: =R32-X32 -> 0 | AE32: =P32/V32 -> 0.83333333 | AF32: =Q32/W32 -> 1.0238095 | AG32: =R32/X32 -> 1 | AJ32: =AA32/V32 -> -0.16666667 | AK32: =AB32/W32 -> 0.023809524 | AL32: =AC32/X32 -> 0 | AN32: x | AO32: Ms. Manusanan Songpichet / Ms. Teeraporn Siritaweewat | AP32: manusanan_son@toyota-asia.com / teeraporn_sir@toyota-asia.com | AQ32: demand sudden decrease in Nov -22% and sudden double increase in Feb
A33: BPK | B33: Packing | E33: 86790-0K051-00 | F33: 86790-0K051-00 | G33: =F33&K33 -> 86790-0K051-00BN | H33: =F33=E33 -> TRUE | I33: W036 | J33: CAMERA ASSY TELEVISION | K33: BN | L33: 975W >>>024J | M33: 25 | N33: BPK | P33: 820 | Q33: 860 | R33: 700 | S33: 660 | V33: 820 | W33: 820 | X33: 670 | AA33: =P33-V33 -> 0 | AB33: =Q33-W33 -> 40 | AC33: =R33-X33 -> 30 | AE33: =P33/V33 -> 1 | AF33: =Q33/W33 -> 1.0487805 | AG33: =R33/X33 -> 1.0447761 | AJ33: =AA33/V33 -> 0 | AK33: =AB33/W33 -> 0.048780488 | AL33: =AC33/X33 -> 0.044776119 | AO33: Ms. Manusanan Songpichet / Ms. Teeraporn Siritaweewat | AP33: manusanan_son@toyota-asia.com / teeraporn_sir@toyota-asia.com
A34: BPK | B34: Packing | E34: 86790-0K051-00 | F34: 86790-0K051-00 | G34: =F34&K34 -> 86790-0K051-00D1 | H34: =F34=E34 -> TRUE | I34: W036 | J34: CAMERA ASSY TELEVISION | K34: D1 | L34: 975W >>>024J | M34: 30 | N34: BPK | O34: =LEFT(E34,11)&N34&D34 -> 86790-0K051BPK | P34: 7560 | Q34: 4200 | R34: 6300 | S34: 7350 | V34: 7830 | W34: 5220 | X34: 7590 | AA34: =P34-V34 -> -270 | AB34: =Q34-W34 -> -1020 | AC34: =R34-X34 -> -1290 | AE34: =P34/V34 -> 0.96551724 | AF34: =Q34/W34 -> 0.8045977 | AG34: =R34/X34 -> 0.83003953 | AJ34: =AA34/V34 -> -0.034482759 | AK34: =AB34/W34 -> -0.1954023 | AL34: =AC34/X34 -> -0.16996047 | AN34: x | AO34: Ms. Manusanan Songpichet / Ms. Teeraporn Siritaweewat | AP34: manusanan_son@toyota-asia.com / teeraporn_sir@toyota-asia.com | AQ34: demand sudden increase in Jan
A35: BPK | B35: Packing | D35: TP1 | E35: 86790-0K110-00 | F35: 86790-0K110-00 | G35: =F35&K35 -> 86790-0K110-00BN | H35: =F35=E35 -> TRUE | I35: M523 | J35: CAMERA ASSY TELEVISION | K35: BN | L35: 975W >>>024J | M35: 10 | N35: BPK | O35: =LEFT(E35,11)&N35&D35 -> 86790-0K110BPKTP1 | P35: 60 | Q35: 80 | R35: 220 | S35: 210 | V35: 150 | W35: 160 | X35: 190 | AA35: =P35-V35 -> -90 | AB35: =Q35-W35 -> -80 | AC35: =R35-X35 -> 30 | AE35: =P35/V35 -> 0.4 | AF35: =Q35/W35 -> 0.5 | AG35: =R35/X35 -> 1.1578947 | AJ35: =AA35/V35 -> -0.6 | AK35: =AB35/W35 -> -0.5 | AL35: =AC35/X35 -> 0.15789474 | AO35: Ms. Manusanan Songpichet / Ms. Teeraporn Siritaweewat | AP35: manusanan_son@toyota-asia.com / teeraporn_sir@toyota-asia.com
A36: BPK | B36: Packing | E36: 86790-0K110-00 | F36: 86790-0K110-00 | G36: =F36&K36 -> 86790-0K110-00D1 | I36: M523 | J36: CAMERA ASSY TELEVISION | K36: D1 | L36: 975W >>>024J | M36: 20 | P36: 5620 | Q36: 3820 | R36: 5240 | S36: 5720 | V36: 5700 | W36: 4100 | X36: 5240 | AA36: =P36-V36 -> -80 | AB36: =Q36-W36 -> -280 | AC36: =R36-X36 -> 0 | AE36: =P36/V36 -> 0.98596491 | AF36: =Q36/W36 -> 0.93170732 | AG36: =R36/X36 -> 1 | AJ36: =AA36/V36 -> -0.014035088 | AK36: =AB36/W36 -> -0.068292683 | AL36: =AC36/X36 -> 0 | AN36: x | AO36: Ms. Manusanan Songpichet / Ms. Teeraporn Siritaweewat | AP36: manusanan_son@toyota-asia.com / teeraporn_sir@toyota-asia.com | AQ36: demand sudden increase in Feb
A37: BPK | B37: Packing | D37: 86790-0K050-00 | E37: 86790-0K120-00 | F37: 86790-0K120-00 | G37: =F37&K37 -> 86790-0K120-00D1 | H37: =F37=E37 -> TRUE | I37: T962 | J37: CAMERA ASSY TELEVISION | K37: D1 | L37: 975W >>>024J | M37: 20 | N37: BPK | O37: =LEFT(E37,11)&N37&D37 -> 86790-0K120BPK86790-0K050-00 | P37: 240 | Q37: 320 | R37: 340 | S37: 280 | T37: BIS | V37: 280 | W37: 320 | X37: 340 | AA37: =P37-V37 -> -40 | AB37: =Q37-W37 -> 0 | AC37: =R37-X37 -> 0 | AE37: =P37/V37 -> 0.85714286 | AF37: =Q37/W37 -> 1 | AG37: =R37/X37 -> 1 | AJ37: =AA37/V37 -> -0.14285714 | AK37: =AB37/W37 -> 0 | AL37: =AC37/X37 -> 0 | AO37: Ms. Manusanan Songpichet / Ms. Teeraporn Siritaweewat | AP37: manusanan_son@toyota-asia.com / teeraporn_sir@toyota-asia.com
A38: BPK | B38: Packing | E38: 86790-0K141-00 | F38: 86790-0K141-00 | G38: =F38&K38 -> 86790-0K141-00BN | I38: U324 | J38: CAMERA ASSY TELEVISION | K38: BN | L38: 975W >>>024J | M38: 8 | P38: 0 | Q38: 0 | R38: 0 | S38: 0 | V38: 0 | W38: 10 | X38: 0 | AA38: =P38-V38 -> 0 | AB38: =Q38-W38 -> -10 | AC38: =R38-X38 -> 0 | AE38: =P38/V38 -> #DIV/0! | AF38: =Q38/W38 -> 0 | AG38: =R38/X38 -> #DIV/0! | AJ38: =AA38/V38 -> #DIV/0! | AK38: =AB38/W38 -> -1 | AL38: =AC38/X38 -> #DIV/0! | AO38: Ms. Manusanan Songpichet / Ms. Teeraporn Siritaweewat | AP38: manusanan_son@toyota-asia.com / teeraporn_sir@toyota-asia.com
A39: BPK | B39: Packing | E39: 86790-0K141-00 | F39: 86790-0K141-00 | G39: =F39&K39 -> 86790-0K141-00D1 | H39: =F39=E39 -> TRUE | I39: U324 | J39: CAMERA ASSY TELEVISION | K39: D1 | L39: 975W >>>024J | M39: 16 | N39: BPK | O39: =LEFT(E39,11)&N39&D39 -> 86790-0K141BPK | P39: 2400 | Q39: 1008 | R39: 1552 | S39: 1920 | V39: 2704 | W39: 1584 | X39: 3008 | AA39: =P39-V39 -> -304 | AB39: =Q39-W39 -> -576 | AC39: =R39-X39 -> -1456 | AE39: =P39/V39 -> 0.88757396 | AF39: =Q39/W39 -> 0.63636364 | AG39: =R39/X39 -> 0.51595745 | AJ39: =AA39/V39 -> -0.11242604 | AK39: =AB39/W39 -> -0.36363636 | AL39: =AC39/X39 -> -0.48404255 | AN39: x | AO39: Ms. Manusanan Songpichet / Ms. Teeraporn Siritaweewat | AP39: manusanan_son@toyota-asia.com / teeraporn_sir@toyota-asia.com | AQ39: demand sudden decrease in Nov -33% and sudden increase in Jan 19%
A40: BPK | B40: Packing | E40: 86790-0K171-00 | F40: 86790-0K171-00 | G40: =F40&K40 -> 86790-0K171-00D1 | I40: U325 | J40: CAMERA ASSY TELEVISION | K40: D1 | L40: 975W >>>024J | M40: 16 | P40: 16 | Q40: 32 | R40: 64 | S40: 80 | V40: 64 | W40: 144 | X40: 112 | AA40: =P40-V40 -> -48 | AB40: =Q40-W40 -> -112 | AC40: =R40-X40 -> -48 | AE40: =P40/V40 -> 0.25 | AF40: =Q40/W40 -> 0.22222222 | AG40: =R40/X40 -> 0.57142857 | AJ40: =AA40/V40 -> -0.75 | AK40: =AB40/W40 -> -0.77777778 | AL40: =AC40/X40 -> -0.42857143 | AO40: Ms. Manusanan Songpichet / Ms. Teeraporn Siritaweewat | AP40: manusanan_son@toyota-asia.com / teeraporn_sir@toyota-asia.com
A41: BPK | B41: Packing | E41: 86790-0K171-00 | F41: 86790-0K171-00 | G41: =F41&K41 -> 86790-0K171-00BN | H41: =F41=E41 -> TRUE | I41: U325 | J41: CAMERA ASSY TELEVISION | K41: BN | L41: 975W >>>024J | M41: 8 | N41: BPK | P41: 480 | Q41: 530 | R41: 400 | S41: 390 | V41: 520 | W41: 560 | X41: 420 | AA41: =P41-V41 -> -40 | AB41: =Q41-W41 -> -30 | AC41: =R41-X41 -> -20 | AE41: =P41/V41 -> 0.92307692 | AF41: =Q41/W41 -> 0.94642857 | AG41: =R41/X41 -> 0.95238095 | AJ41: =AA41/V41 -> -0.076923077 | AK41: =AB41/W41 -> -0.053571429 | AL41: =AC41/X41 -> -0.047619048 | AO41: Ms. Manusanan Songpichet / Ms. Teeraporn Siritaweewat | AP41: manusanan_son@toyota-asia.com / teeraporn_sir@toyota-asia.com
A42: BPK | B42: Packing | E42: 86790-0K181-00 | F42: 86790-0K181-00 | G42: =F42&K42 -> 86790-0K181-00D1 | H42: =F42=E42 -> TRUE | I42: U326 | J42: CAMERA ASSY TELEVISION | K42: D1 | L42: 975W >>>024J | M42: 16 | N42: BPK | O42: =LEFT(E42,11)&N42&D42 -> 86790-0K181BPK | P42: 192 | Q42: 224 | R42: 496 | S42: 480 | V42: 464 | W42: 448 | X42: 496 | AA42: =P42-V42 -> -272 | AB42: =Q42-W42 -> -224 | AC42: =R42-X42 -> 0 | AE42: =P42/V42 -> 0.4137931 | AF42: =Q42/W42 -> 0.5 | AG42: =R42/X42 -> 1 | AJ42: =AA42/V42 -> -0.5862069 | AK42: =AB42/W42 -> -0.5 | AL42: =AC42/X42 -> 0 | AN42: x | AO42: Ms. Manusanan Songpichet / Ms. Teeraporn Siritaweewat | AP42: manusanan_son@toyota-asia.com / teeraporn_sir@toyota-asia.com | AQ42: demand sudden decrease in Nov -33% and sudden increase in Jan 19%
A43: BPK | B43: Packing | E43: 86790-0K190-00 | F43: 86790-0K190-00 | G43: =F43&K43 -> 86790-0K190-00D1 | H43: =F43=E43 -> TRUE | I43: T023 | J43: CAMERA ASSY TELEVISION | K43: D1 | L43: 975W >>>024J | M43: 42 | N43: BPK | O43: =LEFT(E43,11)&N43&D43 -> 86790-0K190BPK | P43: 3486 | Q43: 2142 | R43: 3234 | S43: 3654 | V43: 3638 | W43: 2386 | X43: 3492 | AA43: =P43-V43 -> -152 | AB43: =Q43-W43 -> -244 | AC43: =R43-X43 -> -258 | AE43: =P43/V43 -> 0.9582188 | AF43: =Q43/W43 -> 0.8977368 | AG43: =R43/X43 -> 0.92611684 | AJ43: =AA43/V43 -> -0.041781198 | AK43: =AB43/W43 -> -0.1022632 | AL43: =AC43/X43 -> -0.073883162 | AN43: x | AO43: Ms. Manusanan Songpichet / Ms. Teeraporn Siritaweewat | AP43: manusanan_son@toyota-asia.com / teeraporn_sir@toyota-asia.com | AQ43: demand sudden increase in Feb
A44: BPK | B44: Packing | E44: 86790-0K190-00 | F44: 86790-0K190-00 | G44: =F44&K44 -> 86790-0K190-00BN | H44: =F44=E44 -> TRUE | I44: T023 | J44: CAMERA ASSY TELEVISION | K44: BN | L44: 975W >>>024J | M44: 42 | N44: BPK | O44: =LEFT(E44,11)&N44&D44 -> 86790-0K190BPK | P44: 20 | Q44: 80 | R44: 120 | S44: 110 | V44: 0 | W44: 0 | X44: 0 | AA44: =P44-V44 -> 20 | AB44: =Q44-W44 -> 80 | AC44: =R44-X44 -> 120 | AE44: =P44/V44 -> #DIV/0! | AF44: =Q44/W44 -> #DIV/0! | AG44: =R44/X44 -> #DIV/0! | AJ44: =AA44/V44 -> #DIV/0! | AK44: =AB44/W44 -> #DIV/0! | AL44: =AC44/X44 -> #DIV/0! | AN44: x | AO44: Ms. Manusanan Songpichet / Ms. Teeraporn Siritaweewat | AP44: manusanan_son@toyota-asia.com / teeraporn_sir@toyota-asia.com | AQ44: demand sudden increase in Feb
...

Sheet BP Daily
A1: HEADER | B1: Part No. | C1: Part name | D1: Kanban No. | E1: Start From #Order No. | F1: Remain Order Q'ty (Pcs.) | G1: pending PO Dec | H1: Actual | I1: Start From #Order No. | J1: Remain Order Q'ty (Pcs.)
A2: PLANT CODE | B2: 867900K05100 | C2: CAMERA ASSY TELEVISION | D2: I338 | E2: 2025121601 | F2: 6372 | G2: 659 | H2: =F2-G2 -> 5713 | I2: 2026012701 | J2: 4861
A3: PART TYPE | B3: 867900K14100 | C3: CAMERA ASSY TELEVISION | D3: F165 | E3: 2025121601 | F3: 741 | G3: 152 | H3: =F3-G3 -> 589 | I3: 2026012701 | J3: 677
A4: PRODUCTION MONTH | B4: 867900K17100 | C4: CAMERA ASSY TELEVISION | D4: F320 | E4: 2025121601 | F4: 1407 | G4: 140 | H4: =F4-G4 -> 1267 | I4: 2026012701 | J4: 1258
A5: REVISION TYPE | B5: 867900K23000 | C5: CAMERA ASSY TELEVISION | D5: F530 | E5: 2025121601 | F5: 2911 | G5: 289 | H5: =F5-G5 -> 2622 | I5: 2026012701 | J5: 1851
A6: FORECAST TYPE | B6: F
A7: WOC WEEK | B7: 00-00
A8: REVISION NUMBER | B8: 0
A9: ISSUE DATE | B9: 23/05/2025
A10: REMARKS
A11: DETAILS
Y12: N | BE12: N+1 | CK12: N+2 | DQ12: N+3
A13: PART NUMBER | B13: PART CODE | C13: PART DESC | D13: SUPP CODE | E13: SHIPPING DOCK | F13: DOCK CODE | G13: CAR FAMILY | H13: PACKING SIZE | I13: 1 | J13: 2 | K13: 3 | L13: 4 | M13: 5 | N13: 6 | O13: 7 | P13: 8 | Q13: 9 | R13: 10 | S13: 11 | T13: 12 | U13: 13 | V13: 14 | W13: 15 | X13: 16 | Y13: 17 | Z13: 18 | AA13: 19 | AB13: 20 | AC13: 21 | AD13: 22 | AE13: 23 | AF13: 24 | AG13: 25 | AH13: 26 | AI13: 27 | AJ13: 28 | AK13: 29 | AL13: 30 | AM13: 31 | AN13: N | AO13: 1 | AP13: 2 | AQ13: 3 | AR13: 4 | AS13: 5 | AT13: 6 | AU13: 7 | AV13: 8 | AW13: 9 | AX13: 10 | AY13: 11 | AZ13: 12 | BA13: 13 | BB13: 14 | BC13: 15 | BD13: 16 | BE13: 17 | BF13: 18 | BG13: 19 | BH13: 20 | BI13: 21 | BJ13: 22 | BK13: 23 | BL13: 24 | BM13: 25 | BN13: 26 | BO13: 27 | BP13: 28 | BQ13: 29 | BR13: 30 | BS13: 31 | BT13: N+1 | BU13: 1 | BV13: 2 | BW13: 3 | BX13: 4 | BY13: 5 | BZ13: 6 | CA13: 7 | CB13: 8 | CC13: 9 | CD13: 10 | CE13: 11 | CF13: 12 | CG13: 13 | CH13: 14 | CI13: 15 | CJ13: 16 | CK13: 17 | CL13: 18 | CM13: 19 | CN13: 20 | CO13: 21 | CP13: 22 | CQ13: 23 | CR13: 24 | CS13: 25 | CT13: 26 | CU13: 27 | CV13: 28 | CW13: 29 | CX13: 30 | CY13: 31 | CZ13: N+2 | DA13: 1 | DB13: 2 | DC13: 3 | DD13: 4 | DE13: 5 | DF13: 6 | DG13: 7 | DH13: 8 | DI13: 9 | DJ13: 10 | DK13: 11 | DL13: 12 | DM13: 13 | DN13: 14 | DO13: 15 | DP13: 16 | DQ13: 17 | DR13: 18 | DS13: 19 | DT13: 20 | DU13: 21 | DV13: 22 | DW13: 23 | DX13: 24 | DY13: 25 | DZ13: 26 | EA13: 27 | EB13: 28 | EC13: 29 | ED13: 30 | EE13: 31 | EF13: N+3
A14: 86790-0K051-00 | B14: I338 | C14: CAMERA ASSY TELEVISION | D14: TTETA | E14: MS | F14: P1 | G14: 024J | H14: 25 | I14: 0 | J14: 87 | K14: 85 | L14: 79 | M14: 83 | N14: 83 | O14: 0 | P14: 0 | Q14: 88 | R14: 89 | S14: 88 | T14: 92 | U14: 90 | V14: 77 | W14: 0 | X14: 91 | Y14: 91 | Z14: 88 | AA14: 93 | AB14: 85 | AC14: 0 | AD14: 0 | AE14: 85 | AF14: 89 | AG14: 76 | AH14: 84 | AI14: 84 | AJ14: 84 | AK14: 0 | AL14: 0 | AM14: 0 | AN14: 1891 | AO14: 0 | AP14: 0 | AQ14: 0 | AR14: 83 | AS14: 84 | AT14: 83 | AU14: 39 | AV14: 0 | AW14: 79 | AX14: 79 | AY14: 79 | AZ14: 80 | BA14: 70 | BB14: 65 | BC14: 0 | BD14: 77 | BE14: 80 | BF14: 67 | BG14: 77 | BH14: 76 | BI14: 73 | BJ14: 0 | BK14: 72 | BL14: 69 | BM14: 55 | BN14: 68 | BO14: 61 | BP14: 49 | BQ14: 0 | BR14: 61 | BS14: 51 | BT14: 1677 | BU14: 50 | BV14: 50 | BW14: 50 | BX14: 25 | BY14: 0 | BZ14: 50 | CA14: 50 | CB14: 50 | CC14: 50 | CD14: 49 | CE14: 0 | CF14: 0 | CG14: 0 | CH14: 0 | CI14: 0 | CJ14: 0 | CK14: 0 | CL14: 0 | CM14: 0 | CN14: 50 | CO14: 49 | CP14: 50 | CQ14: 49 | CR14: 50 | CS14: 49 | CT14: 0 | CU14: 50 | CV14: 49 | CW14: 50 | CX14: 49 | CY14: 0 | CZ14: 919 | DA14: 0 | DB14: 0 | DC14: 0 | DD14: 0 | DE14: 0 | DF14: 0 | DG14: 0 | DH14: 0 | DI14: 0 | DJ14: 0 | DK14: 0 | DL14: 0 | DM14: 0 | DN14: 0 | DO14: 0 | DP14: 0 | DQ14: 0 | DR14: 0 | DS14: 0 | DT14: 0 | DU14: 0 | DV14: 0 | DW14: 0 | DX14: 0 | DY14: 0 | DZ14: 0 | EA14: 0 | EB14: 0 | EC14: 0 | ED14: 0 | EE14: 0 | EF14: 0 | EI14: 438D | EJ14: 86790-0K051-00 | EL14: =EJ14=A14 -> TRUE
A15: 86790-0K080-00 | B15: A369 | C15: CAMERA ASSY TELEVISION | D15: TTETA | E15: MS | F15: P1 | G15: 024J | H15: 42 | I15: 0 | J15: 12 | K15: 15 | L15: 12 | M15: 12 | N15: 12 | O15: 0 | P15: 0 | Q15: 17 | R15: 15 | S15: 13 | T15: 12 | U15: 15 | V15: 13 | W15: 0 | X15: 17 | Y15: 14 | Z15: 13 | AA15: 14 | AB15: 14 | AC15: 0 | AD15: 0 | AE15: 16 | AF15: 12 | AG15: 12 | AH15: 13 | AI15: 14 | AJ15: 12 | AK15: 0 | AL15: 0 | AM15: 0 | AN15: 299 | AO15: 0 | AP15: 0 | AQ15: 0 | AR15: 3 | AS15: 5 | AT15: 2 | AU15: 2 | AV15: 0 | AW15: 3 | AX15: 4 | AY15: 2 | AZ15: 3 | BA15: 3 | BB15: 3 | BC15: 0 | BD15: 5 | BE15: 1 | BF15: 4 | BG15: 2 | BH15: 3 | BI15: 3 | BJ15: 0 | BK15: 3 | BL15: 3 | BM15: 2 | BN15: 3 | BO15: 2 | BP15: 2 | BQ15: 0 | BR15: 3 | BS15: 1 | BT15: 67 | BU15: 0 | BV15: 0 | BW15: 0 | BX15: 0 | BY15: 0 | BZ15: 0 | CA15: 0 | CB15: 0 | CC15: 0 | CD15: 0 | CE15: 0 | CF15: 0 | CG15: 0 | CH15: 0 | CI15: 0 | CJ15: 0 | CK15: 0 | CL15: 0 | CM15: 0 | CN15: 0 | CO15: 0 | CP15: 0 | CQ15: 0 | CR15: 0 | CS15: 0 | CT15: 0 | CU15: 0 | CV15: 0 | CW15: 0 | CX15: 0 | CY15: 0 | CZ15: 0 | DA15: 0 | DB15: 0 | DC15: 0 | DD15: 0 | DE15: 0 | DF15: 0 | DG15: 0 | DH15: 0 | DI15: 0 | DJ15: 0 | DK15: 0 | DL15: 0 | DM15: 0 | DN15: 0 | DO15: 0 | DP15: 0 | DQ15: 0 | DR15: 0 | DS15: 0 | DT15: 0 | DU15: 0 | DV15: 0 | DW15: 0 | DX15: 0 | DY15: 0 | DZ15: 0 | EA15: 0 | EB15: 0 | EC15: 0 | ED15: 0 | EE15: 0 | EF15: 0 | EI15: 438D | EJ15: 86790-0K080-00 | EL15: =EJ15=A15 -> TRUE
A16: 86790-0K110-00 | B16: A370 | C16: CAMERA ASSY TELEVISION | D16: TTETA | E16: MS | F16: P1 | G16: 024J | H16: 18 | I16: 0 | J16: 54 | K16: 54 | L16: 51 | M16: 54 | N16: 49 | O16: 0 | P16: 0 | Q16: 58 | R16: 60 | S16: 54 | T16: 58 | U16: 56 | V16: 49 | W16: 0 | X16: 60 | Y16: 55 | Z16: 56 | AA16: 57 | AB16: 57 | AC16: 0 | AD16: 0 | AE16: 56 | AF16: 52 | AG16: 51 | AH16: 54 | AI16: 54 | AJ16: 52 | AK16: 0 | AL16: 0 | AM16: 0 | AN16: 1201 | AO16: 0 | AP16: 0 | AQ16: 0 | AR16: 49 | AS16: 48 | AT16: 49 | AU16: 20 | AV16: 0 | AW16: 44 | AX16: 43 | AY16: 48 | AZ16: 42 | BA16: 41 | BB16: 38 | BC16: 0 | BD16: 43 | BE16: 44 | BF16: 38 | BG16: 47 | BH16: 38 | BI16: 43 | BJ16: 0 | BK16: 43 | BL16: 38 | BM16: 31 | BN16: 39 | BO16: 37 | BP16: 28 | BQ16: 0 | BR16: 36 | BS16: 31 | BT16: 958 | BU16: 30 | BV16: 30 | BW16: 30 | BX16: 15 | BY16: 0 | BZ16: 29 | CA16: 30 | CB16: 29 | CC16: 30 | CD16: 29 | CE16: 0 | CF16: 0 | CG16: 0 | CH16: 0 | CI16: 0 | CJ16: 0 | CK16: 0 | CL16: 0 | CM16: 0 | CN16: 30 | CO16: 29 | CP16: 30 | CQ16: 29 | CR16: 30 | CS16: 29 | CT16: 0 | CU16: 30 | CV16: 29 | CW16: 30 | CX16: 29 | CY16: 0 | CZ16: 547 | DA16: 0 | DB16: 0 | DC16: 0 | DD16: 53 | DE16: 53 | DF16: 53 | DG16: 53 | DH16: 53 | DI16: 53 | DJ16: 0 | DK16: 53 | DL16: 53 | DM16: 52 | DN16: 53 | DO16: 52 | DP16: 26 | DQ16: 0 | DR16: 53 | DS16: 53 | DT16: 52 | DU16: 53 | DV16: 52 | DW16: 53 | DX16: 0 | DY16: 52 | DZ16: 53 | EA16: 52 | EB16: 53 | EC16: 52 | ED16: 0 | EE16: 0 | EF16: 1185 | EI16: 438D | EJ16: 86790-0K110-00 | EL16: =EJ16=A16 -> TRUE
